<?xml version="1.0" ?>
<robot name="fetch_waiter_Zac">

<!-- keep, but edit values to move to origin and remove mass and inertia -->
  <link name="base">
    <inertial>
      <origin rpy="0 0 0" xyz="0 0 0" />
      <mass value="0" />
      <inertia ixx="0" ixy="0" ixz="0" iyy="0" iyz="0" izz="0" />
    </inertial>
    <!-- <visual>
      <origin rpy="0 0 0" xyz="-0.1195 0 -0.3486" />
      <geometry>
        <mesh filename="meshes/torso_lift_link.obj" />
      </geometry>
      <material name="">
        <color rgba="0 0 0 0" />
      </material>
    </visual> -->
    <!-- <collision>
      <origin rpy="0 0 0" xyz="0 0 0" />
      <geometry>
        <mesh filename="meshes/torso_lift_link_collision.STL" />
      </geometry>
    </collision> -->
  </link>

<!-- keep -->
  <link name="shoulder_pan_link">
    <inertial>
      <origin rpy="0 0 0" xyz="0.0927 -0.0056 0.0564" />
      <mass value="0" />
      <inertia ixx="0.0043" ixy="-0.0001" ixz="0.001" iyy="0.0087" iyz="-0.0001" izz="0.0087" />
    </inertial>
    <visual>
      <origin rpy="0 0 0" xyz="0 0 0" />
      <geometry>
        <mesh filename="meshes/shoulder_pan_link.obj" />
      </geometry>
      <material name="">
        <color rgba="1 1 1 1" />
      </material>
    </visual>
    <collision>
      <origin rpy="0 0 0" xyz="0 0 0" />
      <geometry>
        <mesh filename="meshes/shoulder_pan_link_collision.STL" />
      </geometry>
    </collision>
  </link>

<!-- keep but edit origin to be at world origin-->
  <!-- Joint 1 -->
  <joint name="shoulder_pan_joint" type="revolute">
    <origin rpy="0 0 0" xyz="0 0 0" />
    <!-- <origin rpy="0 0 0" xyz="-0.0326 0 0.726" /> -->
    <!-- <origin rpy="0 0 0" xyz="0.119525 0 0.34858" /> -->
    <parent link="base" />
    <child link="shoulder_pan_link" />
    <axis xyz="0 0 1" />
    <dynamics damping="1.0" />
    <limit effort="33.82" lower="-1.6056" upper="1.6056" velocity="1.256" />
  </joint>

<!-- keep -->
  <link name="shoulder_lift_link">
    <inertial>
      <origin rpy="0 0 0" xyz="0.1432 0.0072 -0.0001" />
      <mass value="0" />
      <inertia ixx="0.0028" ixy="-0.0021" ixz="-0.0" iyy="0.0111" iyz="-0.0" izz="0.0112" />
    </inertial>
    <visual>
      <origin rpy="0 0 0" xyz="0 0 0" />
      <geometry>
        <mesh filename="meshes/shoulder_lift_link.obj" />
      </geometry>
      <material name="">
        <color rgba="0.086 0.506 0.767 1" />
      </material>
    </visual>
    <collision>
      <origin rpy="0 0 0" xyz="0 0 0" />
      <geometry>
        <mesh filename="meshes/shoulder_lift_link_collision.STL" />
      </geometry>
    </collision>
  </link>

<!-- keep -->
  <!-- Joint 2 -->
  <joint name="shoulder_lift_joint" type="revolute">
    <origin rpy="0 0 0" xyz="0.117 0 0.0599999999999999" />
    <parent link="shoulder_pan_link" />
    <child link="shoulder_lift_link" />
    <axis xyz="0 1 0" />
    <dynamics damping="1.0" />
    <limit effort="131.76" lower="-1.221" upper="1.518" velocity="1.454" />
  </joint>

<!-- keep -->
  <link name="upperarm_roll_link">
    <inertial>
      <origin rpy="0 0 0" xyz="0.1165 0.0014 0.0000" />
      <mass value="0" />
      <inertia ixx="0.0019" ixy="-0.0001" ixz="0.0" iyy="0.0045" iyz="0.0" izz="0.0047" />
    </inertial>
    <visual>
      <origin rpy="0 0 0" xyz="0 0 0" />
      <geometry>
        <mesh filename="meshes/upperarm_roll_link.obj" />
      </geometry>
      <material name="">
        <color rgba="1 1 1 1" />
      </material>
    </visual>
    <collision>
      <origin rpy="0 0 0" xyz="0 0 0" />
      <geometry>
        <mesh filename="meshes/upperarm_roll_link_collision.STL" />
      </geometry>
    </collision>
  </link>

<!-- keep -->
  <!-- Joint 3 -->
  <joint name="upperarm_roll_joint" type="continuous">
    <origin rpy="0 0 0" xyz="0.219 0 0" />
    <parent link="shoulder_lift_link" />
    <child link="upperarm_roll_link" />
    <axis xyz="1 0 0" />
    <dynamics damping="5.0" />
    <limit effort="76.94" velocity="1.571" />
  </joint>

<!-- keep -->
  <link name="elbow_flex_link">
    <inertial>
      <origin rpy="0 0 0" xyz="0.1279 0.0073 0.0000" />
      <mass value="0" />
      <inertia ixx="0.0024" ixy="-0.0016" ixz="0.0" iyy="0.0082" iyz="-0.0" izz="0.0084" />
    </inertial>
    <visual>
      <origin rpy="0 0 0" xyz="0 0 0" />
      <geometry>
        <mesh filename="meshes/elbow_flex_link.obj" />
      </geometry>
      <material name="">
        <color rgba="0.086 0.506 0.767 1" />
      </material>
    </visual>
    <collision>
      <origin rpy="0 0 0" xyz="0 0 0" />
      <geometry>
        <mesh filename="meshes/elbow_flex_link_collision.STL" />
      </geometry>
    </collision>
  </link>

<!-- keep -->
  <!-- Joint 4 -->
  <joint name="elbow_flex_joint" type="revolute">
    <origin rpy="0 0 0" xyz="0.133 0 0" />
    <parent link="upperarm_roll_link" />
    <child link="elbow_flex_link" />
    <axis xyz="0 1 0" />
    <dynamics damping="1.0" />
    <limit effort="66.18" lower="-2.251" upper="2.251" velocity="1.521" />
  </joint>

<!-- keep -->
  <link name="forearm_roll_link">
    <inertial>
      <origin rpy="0 0 0" xyz="0.1097 -0.0266 0.0000" />
      <mass value="0" />
      <inertia ixx="0.0016" ixy="-0.0003" ixz="0.0" iyy="0.003" iyz="-0.0" izz="0.0035" />
    </inertial>
    <visual>
      <origin rpy="0 0 0" xyz="0 0 0" />
      <geometry>
        <mesh filename="meshes/forearm_roll_link.obj" />
      </geometry>
      <material name="">
        <color rgba="1 1 1 1" />
      </material>
    </visual>
    <collision>
      <origin rpy="0 0 0" xyz="0 0 0" />
      <geometry>
        <mesh filename="meshes/forearm_roll_link_collision.STL" />
      </geometry>
    </collision>
  </link>

<!-- keep -->
  <!-- Joint 5 -->
  <joint name="forearm_roll_joint" type="continuous">
    <origin rpy="0 0 0" xyz="0.197 0 0" />
    <parent link="elbow_flex_link" />
    <child link="forearm_roll_link" />
    <axis xyz="1 0 0" />
    <dynamics damping="5.0" />
    <limit effort="29.35" velocity="1.571" />
  </joint>

<!-- keep -->
  <link name="wrist_flex_link">
    <inertial>
      <origin rpy="0 0 0" xyz="0.0882 0.0009 -0.0001" />
      <mass value="0" />
      <inertia ixx="0.0018" ixy="-0.0001" ixz="-0.0" iyy="0.0042" iyz="0.0" izz="0.0042" />
    </inertial>
    <visual>
      <origin rpy="0 0 0" xyz="0 0 0" />
      <geometry>
        <mesh filename="meshes/wrist_flex_link.obj" />
      </geometry>
      <material name="">
        <color rgba="0.086 0.506 0.767 1" />
      </material>
    </visual>
    <collision>
      <origin rpy="0 0 0" xyz="0 0 0" />
      <geometry>
        <mesh filename="meshes/wrist_flex_link_collision.STL" />
      </geometry>
    </collision>
  </link>

<!-- keep -->
  <!-- Joint 6 -->
  <joint name="wrist_flex_joint" type="revolute">
    <origin rpy="0 0 0" xyz="0.1245 0 0" />
    <parent link="forearm_roll_link" />
    <child link="wrist_flex_link" />
    <axis xyz="0 1 0" />
    <dynamics damping="1.0" />
    <limit effort="25.7" lower="-2.16" upper="2.16" velocity="2.268" />
  </joint>

<!-- keep -->
  <link name="wrist_roll_link">
    <inertial>
      <origin rpy="0 0 0" xyz="0.0095 0.0004 -0.0002" />
      <mass value="0" />
      <inertia ixx="0.0001" ixy="0.0" ixz="0.0" iyy="0.0001" iyz="0.0" izz="0.0001" />
    </inertial>
    <visual>
      <origin rpy="0 0 0" xyz="0 0 0" />
      <geometry>
        <mesh filename="meshes/wrist_roll_link.obj" />
      </geometry>
      <material name="">
        <color rgba="1 1 1 1" />
      </material>
    </visual>
    <collision>
      <origin rpy="0 0 0" xyz="0 0 0" />
      <geometry>
        <mesh filename="meshes/wrist_roll_link_collision.STL" />
      </geometry>
    </collision>
  </link>

<!-- pi/2=1.57079632679 -->
<!-- keep -->
  <!-- Joint 7 -->
  <joint name="wrist_roll_joint" type="continuous">
    <origin rpy="0 0 0" xyz="0.1385 0 0" />
    <parent link="wrist_flex_link" />
    <child link="wrist_roll_link" />
    <axis xyz="1 0 0" />
    <limit effort="7.36" velocity="2.268" />
    <dynamics damping="5.0" />
  </joint>

<!-- keep -->
  <link name="gripper_link">
    <inertial>
      <origin rpy="0 0 0" xyz="-0.0900 -0.0001 -0.0017" />
      <mass value="0" />
      <inertia ixx="0.0013" ixy="-0.0" ixz="0.0" iyy="0.0019" iyz="-0.0" izz="0.0024" />
    </inertial>
    <visual>
      <origin rpy="0 0 0" xyz="0 0 0" />
      <geometry>
        <mesh filename="meshes/gripper_link.obj" />
      </geometry>
    </visual>
    <collision>
      <origin rpy="0 0 0" xyz="0 0 0" />
      <geometry>
        <mesh filename="meshes/gripper_link.STL" />
      </geometry>
    </collision>
  </link>

<!-- keep -->
  <!-- Joint 8 -->
  <joint name="gripper_axis" type="fixed">
    <origin rpy="0 0 0" xyz="0.16645 0 0" />
    <parent link="wrist_roll_link" />
    <child link="gripper_link" />
    <axis xyz="0 1 0" />
  </joint>

<!-- comment out
  <link name="r_gripper_finger_link">
    <inertial>
      <origin rpy="0 0 0" xyz="-0.01 0 0" />
      <mass value="0.0798" />
      <inertia ixx="0.002" ixy="0" ixz="0" iyy="0" iyz="0" izz="0" />
    </inertial>
    <visual>
      <origin rpy="0 0 0" xyz="0 0.101425 0" />
      <geometry>
        <mesh filename="package://fetch_description/meshes/r_gripper_finger_link.STL" />
      </geometry>
      <material name="">
        <color rgba="0.356 0.361 0.376 1" />
      </material>
    </visual>
    <collision>
      <origin rpy="0 0 0" xyz="0 0.101425 0" />
      <geometry>
        <mesh filename="package://fetch_description/meshes/r_gripper_finger_link.STL" />
      </geometry>
    </collision>
  </link>
-->

<!-- comment out
  <joint name="r_gripper_finger_joint" type="prismatic">
    <origin rpy="0 0 0" xyz="0 0.015425 0" />
    <parent link="gripper_link" />
    <child link="r_gripper_finger_link" />
    <axis xyz="0 1 0" />
    <limit effort="60" lower="0.0" upper="0.05" velocity="0.05" /><dynamics damping="100.0" />
  </joint>
-->
  <!-- <origin rpy="0 0 0" xyz="0 0.045 0" /> -->
  <!-- <limit effort="200" lower="0.0" upper="0.05" velocity="0.05" /><dynamics damping="100.0" /></joint> -->

<!-- comment out
  <link name="l_gripper_finger_link">
    <inertial>
      <origin rpy="0 0 0" xyz="-0.01 0 0" />
      <mass value="0.0798" />
      <inertia ixx="0.002" ixy="0" ixz="0" iyy="0" iyz="0" izz="0" />
    </inertial>
    <visual>
      <origin rpy="0 0 0" xyz="0 -0.101425 0" />
      <geometry>
        <mesh filename="package://fetch_description/meshes/l_gripper_finger_link.STL" />
      </geometry>
      <material name="">
        <color rgba="0.356 0.361 0.376 1" />
      </material>
    </visual>
    <collision>
      <origin rpy="0 0 0" xyz="0 -0.101425 0" />
      <geometry>
        <mesh filename="package://fetch_description/meshes/l_gripper_finger_link.STL" />
      </geometry>
    </collision>
  </link>
-->

<!-- comment out
  <joint name="l_gripper_finger_joint" type="prismatic">
    <origin rpy="0 0 0" xyz="0 -0.015425 0" />
    <parent link="gripper_link" />
    <child link="l_gripper_finger_link" />
    <axis xyz="0 -1 0" />
    <limit effort="60" lower="0.0" upper="0.05" velocity="0.05" /><dynamics damping="100.0" />
  </joint>
-->
  <!-- <origin rpy="0 0 0" xyz="0 -0.045 0" /> -->
  <!-- <limit effort="200" lower="0.0" upper="0.05" velocity="0.05" /><dynamics damping="100.0" /> </joint>-->


<!-- object code -->

  <!-- Note that this home position is tilted 90 deg about the x-axis 
  so the tray is vertical so any initial configuration should include a 
  rotation about the x-axis so it is feasible -->
  
  <!-- Joint 9 -->
  <joint name="waiter_tray_joint" type="fixed">
     <origin rpy="0 0 0" xyz="0.1524 0 0" />
     <parent link="gripper_link" />
     <child link="waiter_tray_link" />
  </joint>

  <!-- need to add known inertia values. assumed that the joint is aligned with the 
  principal axes of the tray. Currently assuming that the tray is grasped at the 
  COM? Need to change so that there is ixy etc? -->

  <link name="waiter_tray_link">
    <inertial>
      <origin rpy="0 0 0" xyz="0 0 0" />
      <mass value="0" />
      <inertia ixx="0.0077" ixy="0" ixz="0" iyy="0.0155" iyz="0" izz="0.0077" />
    </inertial>
    <visual>
      <origin rpy="0 0 0" xyz="0 0 0"/>
      <geometry>
        <mesh filename="meshes/ServingTray_metric_rotated_scaled_shifted.STL" />
          <!-- scale="0.001 0.001 0.001" -->
      </geometry>
      <material name="">
      <color rgba="1 1 1 1" />
      </material>
    </visual>
    <collision>
      <origin rpy="0 0 0" xyz="0 0 0"/>
      <geometry>
        <mesh filename="meshes/ServingTray_metric_rotated_scaled_shifted.STL" />
          <!-- scale="0.001 0.001 0.001" -->
      </geometry>
    </collision>
  </link>

</robot>
